Workbook

Sheet 汇总（8-12月）
A1: RED 预算·实绩 汇总（2026年8月〜12月） ※由各月页自动汇总，请勿编辑
A2: 按付款月＝该月实际支付的金额（联动预实对比表）／按投放月＝该月实际投放的广告（用于判断投放效率）
A4: ■ ① 实际支出【按付款月·元】
A5: 费用类别 | B5: 2026-08 | C5: 2026-09 | D5: 2026-10 | E5: 2026-11 | F5: 2026-12 | G5: 合计 | H5: 预实对比表科目
A6: 筆記+直播 | B6: ='2026-08'!F5 -> 81430 | C6: ='2026-09'!F5 -> 0 | D6: ='2026-10'!F5 -> 0 | E6: ='2026-11'!F5 -> 0 | F6: ='2026-12'!F5 -> 0 | G6: =SUM(B6:F6) -> 81430 | H6: 站外种草(Red)
A7: 直播坑位费 | B7: ='2026-08'!F6 -> 12332 | C7: ='2026-09'!F6 -> 0 | D7: ='2026-10'!F6 -> 0 | E7: ='2026-11'!F6 -> 0 | F7: ='2026-12'!F6 -> 0 | G7: =SUM(B7:F7) -> 12332 | H7: 站外种草(Red)
A8: KOC圖文 | B8: ='2026-08'!F7 -> 5367.76 | C8: ='2026-09'!F7 -> 0 | D8: ='2026-10'!F7 -> 0 | E8: ='2026-11'!F7 -> 0 | F8: ='2026-12'!F7 -> 0 | G8: =SUM(B8:F8) -> 5367.76 | H8: 站外种草(Red)
A9: 視頻筆記預算 | B9: ='2026-08'!F8 -> 10010 | C9: ='2026-09'!F8 -> 0 | D9: ='2026-10'!F8 -> 0 | E9: ='2026-11'!F8 -> 0 | F9: ='2026-12'!F8 -> 0 | G9: =SUM(B9:F9) -> 10010 | H9: 站外种草(Red)
A10: koc動画不报备 | B10: ='2026-08'!F9 -> 1150 | C10: ='2026-09'!F9 -> 0 | D10: ='2026-10'!F9 -> 0 | E10: ='2026-11'!F9 -> 0 | F10: ='2026-12'!F9 -> 0 | G10: =SUM(B10:F10) -> 1150 | H10: 站外种草(Red)
A11: 样品费 | B11: ='2026-08'!F10 -> 3643.8 | C11: ='2026-09'!F10 -> 0 | D11: ='2026-10'!F10 -> 0 | E11: ='2026-11'!F10 -> 0 | F11: ='2026-12'!F10 -> 0 | G11: =SUM(B11:F11) -> 3643.8 | H11: ★无预算科目
A12: 运费 | B12: ='2026-08'!F11 -> 762.3 | C12: ='2026-09'!F11 -> 0 | D12: ='2026-10'!F11 -> 0 | E12: ='2026-11'!F11 -> 0 | F12: ='2026-12'!F11 -> 0 | G12: =SUM(B12:F12) -> 762.3 | H12: ★无预算科目
A13: 風險保證金 | B13: ='2026-08'!F12 -> 3370 | C13: ='2026-09'!F12 -> 0 | D13: ='2026-10'!F12 -> 0 | E13: ='2026-11'!F12 -> 0 | F13: ='2026-12'!F12 -> 0 | G13: =SUM(B13:F13) -> 3370 | H13: ★无预算科目
A14: 小紅書專業號年審費用 | B14: ='2026-08'!F13 -> 600 | C14: ='2026-09'!F13 -> 0 | D14: ='2026-10'!F13 -> 0 | E14: ='2026-11'!F13 -> 0 | F14: ='2026-12'!F13 -> 0 | G14: =SUM(B14:F14) -> 600 | H14: ★无预算科目
A15: 合计 | B15: =SUM(B6:B14) -> 118665.86 | C15: =SUM(C6:C14) -> 0 | D15: =SUM(D6:D14) -> 0 | E15: =SUM(E6:E14) -> 0 | F15: =SUM(F6:F14) -> 0 | G15: =SUM(G6:G14) -> 118665.86
A16: 其中 站外种草(Red)＝联动预实对比表 | B16: =SUMIF($H$6:$H$14,"站外种草(Red)",B$6:B$14) -> 110289.76 | C16: =SUMIF($H$6:$H$14,"站外种草(Red)",C$6:C$14) -> 0 | D16: =SUMIF($H$6:$H$14,"站外种草(Red)",D$6:D$14) -> 0 | E16: =SUMIF($H$6:$H$14,"站外种草(Red)",E$6:E$14) -> 0 | F16: =SUMIF($H$6:$H$14,"站外种草(Red)",F$6:F$14) -> 0 | G16: =SUM(B16:F16) -> 110289.76
A17: 其中 无预算科目 | B17: =SUMIF($H$6:$H$14,"★无预算科目",B$6:B$14) -> 8376.1 | C17: =SUMIF($H$6:$H$14,"★无预算科目",C$6:C$14) -> 0 | D17: =SUMIF($H$6:$H$14,"★无预算科目",D$6:D$14) -> 0 | E17: =SUMIF($H$6:$H$14,"★无预算科目",E$6:E$14) -> 0 | F17: =SUMIF($H$6:$H$14,"★无预算科目",F$6:F$14) -> 0 | G17: =SUM(B17:F17) -> 8376.1
A19: ■ ② 预算【按付款月·元】
A20: 费用类别 | B20: 2026-08 | C20: 2026-09 | D20: 2026-10 | E20: 2026-11 | F20: 2026-12 | G20: 合计 | H20: 预实对比表科目
A21: 筆記+直播 | B21: ='2026-08'!D5 -> 99600 | C21: ='2026-09'!D5 | D21: ='2026-10'!D5 | E21: ='2026-11'!D5 | F21: ='2026-12'!D5 | G21: =SUM(B21:F21) -> 99600 | H21: 站外种草(Red)
A22: 直播坑位费 | B22: ='2026-08'!D6 -> 15000 | C22: ='2026-09'!D6 | D22: ='2026-10'!D6 | E22: ='2026-11'!D6 | F22: ='2026-12'!D6 | G22: =SUM(B22:F22) -> 15000 | H22: 站外种草(Red)
A23: KOC圖文 | B23: ='2026-08'!D7 -> 26250 | C23: ='2026-09'!D7 | D23: ='2026-10'!D7 | E23: ='2026-11'!D7 | F23: ='2026-12'!D7 | G23: =SUM(B23:F23) -> 26250 | H23: 站外种草(Red)
A24: 視頻筆記預算 | B24: ='2026-08'!D8 -> 1500 | C24: ='2026-09'!D8 | D24: ='2026-10'!D8 | E24: ='2026-11'!D8 | F24: ='2026-12'!D8 | G24: =SUM(B24:F24) -> 1500 | H24: 站外种草(Red)
A25: koc動画不报备 | B25: ='2026-08'!D9 -> 7500 | C25: ='2026-09'!D9 | D25: ='2026-10'!D9 | E25: ='2026-11'!D9 | F25: ='2026-12'!D9 | G25: =SUM(B25:F25) -> 7500 | H25: 站外种草(Red)
A26: 样品费 | B26: ='2026-08'!D10 -> 3500 | C26: ='2026-09'!D10 | D26: ='2026-10'!D10 | E26: ='2026-11'!D10 | F26: ='2026-12'!D10 | G26: =SUM(B26:F26) -> 3500 | H26: ★无预算科目
A27: 运费 | B27: ='2026-08'!D11 -> 1000 | C27: ='2026-09'!D11 | D27: ='2026-10'!D11 | E27: ='2026-11'!D11 | F27: ='2026-12'!D11 | G27: =SUM(B27:F27) -> 1000 | H27: ★无预算科目
A28: 風險保證金 | B28: ='2026-08'!D12 -> 3400 | C28: ='2026-09'!D12 | D28: ='2026-10'!D12 | E28: ='2026-11'!D12 | F28: ='2026-12'!D12 | G28: =SUM(B28:F28) -> 3400 | H28: ★无预算科目
A29: 小紅書專業號年審費用 | B29: ='2026-08'!D13 -> 600 | C29: ='2026-09'!D13 | D29: ='2026-10'!D13 | E29: ='2026-11'!D13 | F29: ='2026-12'!D13 | G29: =SUM(B29:F29) -> 600 | H29: ★无预算科目
A30: 合计 | B30: =SUM(B21:B29) -> 158350 | C30: =SUM(C21:C29) -> 0 | D30: =SUM(D21:D29) -> 0 | E30: =SUM(E21:E29) -> 0 | F30: =SUM(F21:F29) -> 0 | G30: =SUM(G21:G29) -> 158350
A32: ■ ③ 执行率（①÷②）
A33: 费用类别 | B33: 2026-08 | C33: 2026-09 | D33: 2026-10 | E33: 2026-11 | F33: 2026-12 | G33: 合计
A34: 筆記+直播 | B34: =IFERROR(IF(N(B21)=0,"",B6/B21),"") -> 0.81757028 | C34: =IFERROR(IF(N(C21)=0,"",C6/C21),"") | D34: =IFERROR(IF(N(D21)=0,"",D6/D21),"") | E34: =IFERROR(IF(N(E21)=0,"",E6/E21),"") | F34: =IFERROR(IF(N(F21)=0,"",F6/F21),"") | G34: =IFERROR(IF(N(G21)=0,"",G6/G21),"") -> 0.81757028
A35: 直播坑位费 | B35: =IFERROR(IF(N(B22)=0,"",B7/B22),"") -> 0.82213333 | C35: =IFERROR(IF(N(C22)=0,"",C7/C22),"") | D35: =IFERROR(IF(N(D22)=0,"",D7/D22),"") | E35: =IFERROR(IF(N(E22)=0,"",E7/E22),"") | F35: =IFERROR(IF(N(F22)=0,"",F7/F22),"") | G35: =IFERROR(IF(N(G22)=0,"",G7/G22),"") -> 0.82213333
A36: KOC圖文 | B36: =IFERROR(IF(N(B23)=0,"",B8/B23),"") -> 0.2044861 | C36: =IFERROR(IF(N(C23)=0,"",C8/C23),"") | D36: =IFERROR(IF(N(D23)=0,"",D8/D23),"") | E36: =IFERROR(IF(N(E23)=0,"",E8/E23),"") | F36: =IFERROR(IF(N(F23)=0,"",F8/F23),"") | G36: =IFERROR(IF(N(G23)=0,"",G8/G23),"") -> 0.2044861
A37: 視頻筆記預算 | B37: =IFERROR(IF(N(B24)=0,"",B9/B24),"") -> 6.6733333 | C37: =IFERROR(IF(N(C24)=0,"",C9/C24),"") | D37: =IFERROR(IF(N(D24)=0,"",D9/D24),"") | E37: =IFERROR(IF(N(E24)=0,"",E9/E24),"") | F37: =IFERROR(IF(N(F24)=0,"",F9/F24),"") | G37: =IFERROR(IF(N(G24)=0,"",G9/G24),"") -> 6.6733333
A38: koc動画不报备 | B38: =IFERROR(IF(N(B25)=0,"",B10/B25),"") -> 0.15333333 | C38: =IFERROR(IF(N(C25)=0,"",C10/C25),"") | D38: =IFERROR(IF(N(D25)=0,"",D10/D25),"") | E38: =IFERROR(IF(N(E25)=0,"",E10/E25),"") | F38: =IFERROR(IF(N(F25)=0,"",F10/F25),"") | G38: =IFERROR(IF(N(G25)=0,"",G10/G25),"") -> 0.15333333
A39: 样品费 | B39: =IFERROR(IF(N(B26)=0,"",B11/B26),"") -> 1.0410857 | C39: =IFERROR(IF(N(C26)=0,"",C11/C26),"") | D39: =IFERROR(IF(N(D26)=0,"",D11/D26),"") | E39: =IFERROR(IF(N(E26)=0,"",E11/E26),"") | F39: =IFERROR(IF(N(F26)=0,"",F11/F26),"") | G39: =IFERROR(IF(N(G26)=0,"",G11/G26),"") -> 1.0410857
A40: 运费 | B40: =IFERROR(IF(N(B27)=0,"",B12/B27),"") -> 0.7623 | C40: =IFERROR(IF(N(C27)=0,"",C12/C27),"") | D40: =IFERROR(IF(N(D27)=0,"",D12/D27),"") | E40: =IFERROR(IF(N(E27)=0,"",E12/E27),"") | F40: =IFERROR(IF(N(F27)=0,"",F12/F27),"") | G40: =IFERROR(IF(N(G27)=0,"",G12/G27),"") -> 0.7623
A41: 風險保證金 | B41: =IFERROR(IF(N(B28)=0,"",B13/B28),"") -> 0.99117647 | C41: =IFERROR(IF(N(C28)=0,"",C13/C28),"") | D41: =IFERROR(IF(N(D28)=0,"",D13/D28),"") | E41: =IFERROR(IF(N(E28)=0,"",E13/E28),"") | F41: =IFERROR(IF(N(F28)=0,"",F13/F28),"") | G41: =IFERROR(IF(N(G28)=0,"",G13/G28),"") -> 0.99117647
A42: 小紅書專業號年審費用 | B42: =IFERROR(IF(N(B29)=0,"",B14/B29),"") -> 1 | C42: =IFERROR(IF(N(C29)=0,"",C14/C29),"") | D42: =IFERROR(IF(N(D29)=0,"",D14/D29),"") | E42: =IFERROR(IF(N(E29)=0,"",E14/E29),"") | F42: =IFERROR(IF(N(F29)=0,"",F14/F29),"") | G42: =IFERROR(IF(N(G29)=0,"",G14/G29),"") -> 1
A44: ■ ④ 按投放月【该月实际投放的广告·元】 ※判断投放合理性看这里
...

Sheet 2026-08
A1: Quality 1st 面膜 · RED 预算与支出 2026-08
A2: 【填写规则】本页放置「本月已付款」的支出。若实际投放在次月及以后，请在 B列★投放月 填写实际投放的月份。
A3: 一、预算总览（自动汇总）
A4: 费用类别 | D4: 预算（元） | F4: 实际支出（元） | H4: 差额 | I4: 执行率 | J4: 预实对比表科目
A5: 筆記+直播 | D5: 99600 | F5: =SUMIF($C$18:$C$77,$A5,$G$18:$G$77) -> 81430 | H5: =IF(N(D5)=0,"",D5-F5) -> 18170 | I5: =IF(N(D5)=0,"",F5/D5) -> 0.81757028 | J5: 站外种草(Red)
A6: 直播坑位费 | D6: 15000 | F6: =SUMIF($C$18:$C$77,$A6,$G$18:$G$77) -> 12332 | H6: =IF(N(D6)=0,"",D6-F6) -> 2668 | I6: =IF(N(D6)=0,"",F6/D6) -> 0.82213333 | J6: 站外种草(Red)
A7: KOC圖文 | D7: 26250 | F7: =SUMIF($C$18:$C$77,$A7,$G$18:$G$77) -> 5367.76 | H7: =IF(N(D7)=0,"",D7-F7) -> 20882.24 | I7: =IF(N(D7)=0,"",F7/D7) -> 0.2044861 | J7: 站外种草(Red)
A8: 視頻筆記預算 | D8: 1500 | F8: =SUMIF($C$18:$C$77,$A8,$G$18:$G$77) -> 10010 | H8: =IF(N(D8)=0,"",D8-F8) -> -8510 | I8: =IF(N(D8)=0,"",F8/D8) -> 6.6733333 | J8: 站外种草(Red)
A9: koc動画不报备 | D9: 7500 | F9: =SUMIF($C$18:$C$77,$A9,$G$18:$G$77) -> 1150 | H9: =IF(N(D9)=0,"",D9-F9) -> 6350 | I9: =IF(N(D9)=0,"",F9/D9) -> 0.15333333 | J9: 站外种草(Red)
A10: 样品费 | D10: 3500 | F10: =SUMIF($C$18:$C$77,$A10,$G$18:$G$77) -> 3643.8 | H10: =IF(N(D10)=0,"",D10-F10) -> -143.8 | I10: =IF(N(D10)=0,"",F10/D10) -> 1.0410857 | J10: ★无预算科目
A11: 运费 | D11: 1000 | F11: =SUMIF($C$18:$C$77,$A11,$G$18:$G$77) -> 762.3 | H11: =IF(N(D11)=0,"",D11-F11) -> 237.7 | I11: =IF(N(D11)=0,"",F11/D11) -> 0.7623 | J11: ★无预算科目
A12: 風險保證金 | D12: 3400 | F12: =SUMIF($C$18:$C$77,$A12,$G$18:$G$77) -> 3370 | H12: =IF(N(D12)=0,"",D12-F12) -> 30 | I12: =IF(N(D12)=0,"",F12/D12) -> 0.99117647 | J12: ★无预算科目
A13: 小紅書專業號年審費用 | D13: 600 | F13: =SUMIF($C$18:$C$77,$A13,$G$18:$G$77) -> 600 | H13: =IF(N(D13)=0,"",D13-F13) -> 0 | I13: =IF(N(D13)=0,"",F13/D13) -> 1 | J13: ★无预算科目
A14: 合计 | D14: =SUM(D5:D13) -> 158350 | F14: =SUM(F5:F13) -> 118665.86 | H14: =IF(N(D14)=0,"",D14-F14) -> 39684.14 | I14: =IF(N(D14)=0,"",F14/D14) -> 0.74938971
A16: 二、支出明细 【★付款日期 与 ★投放月 为必填项。金额＝数量×单价】
A17: ★付款日期 | B17: ★投放月 | C17: 费用类别 | D17: 博主名称 | E17: 用途·合作条件 | F17: 直播产品 | G17: 金额（税入·元） | H17: 支付方式 | I17: 付款主体 | J17: 销售额（元） | K17: 投产比 | L17: 产出·笔记链接
B18: 2026-08 | C18: 筆記+直播 | D18: 较真儿的peny | E18: （笔记1w软植入）+20% 讲解1场+后 | F18: 金色, 黑银色 | G18: 3030 | H18: 对公转账 | I18: Sakura | J18: 11825 | K18: =IF(OR(N($J18)=0,N($G18)=0),"",$J18/$G18) -> 3.9026403
B19: 2026-08 | C19: 筆記+直播 | D19: 欧淋莉 | E19: 20000保比roi为3 | F19: 金色, 黑银色 | G19: 23320 | H19: 对公转账 | I19: Sakura | K19: =IF(OR(N($J19)=0,N($G19)=0),"",$J19/$G19)
B20: 2026-08 | C20: 筆記+直播 | D20: 如酱在日本 | E20: 框架，6场直播，线上佣金25% | F20: 金色 | G20: 55080 | H20: 对公转账 | I20: Sakura | J20: 12350 | K20: =IF(OR(N($J20)=0,N($G20)=0),"",$J20/$G20) -> 0.22421932
B21: 2026-08 | C21: 直播坑位费 | D21: 岸川在日本 | E21: 25000保比2500 | F21: 金色, 黑银色, 黑金色, 蓝色, 银色 | G21: 10000 | H21: 直付达人 | I21: Sakura | K21: =IF(OR(N($J21)=0,N($G21)=0),"",$J21/$G21)
B22: 2026-08 | C22: 直播坑位费 | D22: 佳小蔓的逆龄日记 | E22: 1场直播+挂链上播 | F22: 黑银色, 金色 | G22: 2332 | H22: 对公转账 | I22: Sakura | J22: 4300 | K22: =IF(OR(N($J22)=0,N($G22)=0),"",$J22/$G22) -> 1.8439108
B23: 2026-08 | C23: 視頻筆記預算 | D23: 一只小椰子 | E23: 视频笔记 | F23: 金色 | G23: 1320 | H23: 蒲公英充值 | I23: Sakura | K23: =IF(OR(N($J23)=0,N($G23)=0),"",$J23/$G23)
B24: 2026-08 | C24: 視頻筆記預算 | D24: 小冷月儿 | E24: 视频笔记 | F24: 金色 | G24: 1870 | H24: 蒲公英充值 | I24: Q1 | K24: =IF(OR(N($J24)=0,N($G24)=0),"",$J24/$G24)
B25: 2026-08 | C25: 視頻筆記預算 | D25: 大孟孟爱护肤 | E25: 视频笔记 | F25: 金色 | G25: 660 | H25: 蒲公英充值 | I25: Q1 | K25: =IF(OR(N($J25)=0,N($G25)=0),"",$J25/$G25)
B26: 2026-08 | C26: 視頻筆記預算 | D26: 菌菌睡不醒 | E26: 视频笔记 | F26: 金色 | G26: 2090 | H26: 蒲公英充值 | I26: Q1 | K26: =IF(OR(N($J26)=0,N($G26)=0),"",$J26/$G26)
B27: 2026-08 | C27: 視頻筆記預算 | D27: 还得是花花大王 | E27: 视频笔记 | F27: 金色 | G27: 1650 | H27: 蒲公英充值 | I27: Q1 | K27: =IF(OR(N($J27)=0,N($G27)=0),"",$J27/$G27)
B28: 2026-08 | C28: 視頻筆記預算 | D28: 一只美柚子 | E28: 视频笔记 | F28: 金色 | G28: 1320 | H28: 蒲公英充值 | I28: Q1 | K28: =IF(OR(N($J28)=0,N($G28)=0),"",$J28/$G28)
B29: 2026-08 | C29: 視頻筆記預算 | D29: 芋泥奶酪毬 | E29: 视频笔记 | F29: 金色 | G29: 1100 | H29: 蒲公英充值 | I29: Q1 | K29: =IF(OR(N($J29)=0,N($G29)=0),"",$J29/$G29)
B30: 2026-08 | C30: KOC圖文 | D30: 一碟碎碎冰 | E30: 图文笔记/绑定小红星 | F30: 金色 | G30: 820.4 | H30: 对公转账 | I30: Sakura | K30: =IF(OR(N($J30)=0,N($G30)=0),"",$J30/$G30)
B31: 2026-08 | C31: KOC圖文 | D31: 露露 Clover | E31: 图文笔记/绑定小红星 | F31: 金色 | G31: 937.6 | H31: 对公转账 | I31: Sakura | K31: =IF(OR(N($J31)=0,N($G31)=0),"",$J31/$G31)
B32: 2026-08 | C32: KOC圖文 | D32: 小鸟大王 | E32: 图文笔记/绑定小红星 | F32: 金色 | G32: 1172 | H32: 对公转账 | I32: Sakura | K32: =IF(OR(N($J32)=0,N($G32)=0),"",$J32/$G32)
B33: 2026-08 | C33: KOC圖文 | D33: 快樂逃跑了 | E33: 图文笔记/绑定小红星 | F33: 金色 | G33: 937.6 | H33: 对公转账 | I33: Sakura | K33: =IF(OR(N($J33)=0,N($G33)=0),"",$J33/$G33)
B34: 2026-08 | C34: KOC圖文 | D34: 熙熙不稀稀 | E34: 图文笔记/绑定小红星 | F34: 金色 | G34: 914.16 | H34: 对公转账 | I34: Sakura | K34: =IF(OR(N($J34)=0,N($G34)=0),"",$J34/$G34)
B35: 2026-08 | C35: KOC圖文 | D35: 喝点小九 | E35: 图文笔记/绑定小红星 | F35: 金色 | G35: 586 | H35: 对公转账 | I35: Sakura | K35: =IF(OR(N($J35)=0,N($G35)=0),"",$J35/$G35)
B36: 2026-08 | C36: koc動画不报备 | F36: 金色 | G36: 600 | H36: 直付达人 | I36: Sakura | K36: =IF(OR(N($J36)=0,N($G36)=0),"",$J36/$G36)
B37: 2026-08 | C37: koc動画不报备 | F37: 金色 | G37: 550 | H37: 直付达人 | I37: Sakura | K37: =IF(OR(N($J37)=0,N($G37)=0),"",$J37/$G37)
B38: 2026-08 | C38: 样品费 | E38: 拍单36包/天猫 | F38: 金色 | G38: 1227.2 | H38: 其他 | I38: Sakura | K38: =IF(OR(N($J38)=0,N($G38)=0),"",$J38/$G38)
B39: 2026-08 | C39: 样品费 | E39: 拍单6包黑/天猫 | F39: 黑金色 | G39: 319.6 | H39: 其他 | I39: Sakura | K39: =IF(OR(N($J39)=0,N($G39)=0),"",$J39/$G39)
B40: 2026-08 | C40: 样品费 | E40: 拍单4/小红书 | F40: 金色 | G40: 257 | H40: 其他 | I40: Sakura | K40: =IF(OR(N($J40)=0,N($G40)=0),"",$J40/$G40)
B41: 2026-08 | C41: 样品费 | E41: 拍单27/小红书 | F41: 蓝色 | G41: 1293 | H41: 其他 | I41: Sakura | K41: =IF(OR(N($J41)=0,N($G41)=0),"",$J41/$G41)
...

Sheet 2026-09
A1: Quality 1st 面膜 · RED 预算与支出 2026-09
A2: 【填写规则】本页放置「本月已付款」的支出。若实际投放在次月及以后，请在 B列★投放月 填写实际投放的月份。
A3: 一、预算总览（自动汇总）
A4: 费用类别 | D4: 预算（元） | F4: 实际支出（元） | H4: 差额 | I4: 执行率 | J4: 预实对比表科目
A5: 筆記+直播 | F5: =SUMIF($C$18:$C$77,$A5,$G$18:$G$77) -> 0 | H5: =IF(N(D5)=0,"",D5-F5) | I5: =IF(N(D5)=0,"",F5/D5) | J5: 站外种草(Red)
A6: 直播坑位费 | F6: =SUMIF($C$18:$C$77,$A6,$G$18:$G$77) -> 0 | H6: =IF(N(D6)=0,"",D6-F6) | I6: =IF(N(D6)=0,"",F6/D6) | J6: 站外种草(Red)
A7: KOC圖文 | F7: =SUMIF($C$18:$C$77,$A7,$G$18:$G$77) -> 0 | H7: =IF(N(D7)=0,"",D7-F7) | I7: =IF(N(D7)=0,"",F7/D7) | J7: 站外种草(Red)
A8: 視頻筆記預算 | F8: =SUMIF($C$18:$C$77,$A8,$G$18:$G$77) -> 0 | H8: =IF(N(D8)=0,"",D8-F8) | I8: =IF(N(D8)=0,"",F8/D8) | J8: 站外种草(Red)
A9: koc動画不报备 | F9: =SUMIF($C$18:$C$77,$A9,$G$18:$G$77) -> 0 | H9: =IF(N(D9)=0,"",D9-F9) | I9: =IF(N(D9)=0,"",F9/D9) | J9: 站外种草(Red)
A10: 样品费 | F10: =SUMIF($C$18:$C$77,$A10,$G$18:$G$77) -> 0 | H10: =IF(N(D10)=0,"",D10-F10) | I10: =IF(N(D10)=0,"",F10/D10) | J10: ★无预算科目
A11: 运费 | F11: =SUMIF($C$18:$C$77,$A11,$G$18:$G$77) -> 0 | H11: =IF(N(D11)=0,"",D11-F11) | I11: =IF(N(D11)=0,"",F11/D11) | J11: ★无预算科目
A12: 風險保證金 | F12: =SUMIF($C$18:$C$77,$A12,$G$18:$G$77) -> 0 | H12: =IF(N(D12)=0,"",D12-F12) | I12: =IF(N(D12)=0,"",F12/D12) | J12: ★无预算科目
A13: 小紅書專業號年審費用 | F13: =SUMIF($C$18:$C$77,$A13,$G$18:$G$77) -> 0 | H13: =IF(N(D13)=0,"",D13-F13) | I13: =IF(N(D13)=0,"",F13/D13) | J13: ★无预算科目
A14: 合计 | D14: =SUM(D5:D13) -> 0 | F14: =SUM(F5:F13) -> 0 | H14: =IF(N(D14)=0,"",D14-F14) | I14: =IF(N(D14)=0,"",F14/D14)
A16: 二、支出明细 【★付款日期 与 ★投放月 为必填项。金额＝数量×单价】
A17: ★付款日期 | B17: ★投放月 | C17: 费用类别 | D17: 博主名称 | E17: 用途·合作条件 | F17: 直播产品 | G17: 金额（税入·元） | H17: 支付方式 | I17: 付款主体 | J17: 销售额（元） | K17: 投产比 | L17: 产出·笔记链接
K18: =IF(OR(N($J18)=0,N($G18)=0),"",$J18/$G18)
K19: =IF(OR(N($J19)=0,N($G19)=0),"",$J19/$G19)
K20: =IF(OR(N($J20)=0,N($G20)=0),"",$J20/$G20)
K21: =IF(OR(N($J21)=0,N($G21)=0),"",$J21/$G21)
K22: =IF(OR(N($J22)=0,N($G22)=0),"",$J22/$G22)
K23: =IF(OR(N($J23)=0,N($G23)=0),"",$J23/$G23)
K24: =IF(OR(N($J24)=0,N($G24)=0),"",$J24/$G24)
K25: =IF(OR(N($J25)=0,N($G25)=0),"",$J25/$G25)
K26: =IF(OR(N($J26)=0,N($G26)=0),"",$J26/$G26)
K27: =IF(OR(N($J27)=0,N($G27)=0),"",$J27/$G27)
K28: =IF(OR(N($J28)=0,N($G28)=0),"",$J28/$G28)
K29: =IF(OR(N($J29)=0,N($G29)=0),"",$J29/$G29)
... K77: =IF(OR(N($J77)=0,N($G77)=0),"",$J77/$G77)
A78: 合计 | G78: =SUM(G18:G77) -> 0 | J78: =SUM(J18:J77) -> 0 | K78: =IFERROR(J78/G78,"")

Sheet 2026-10
A1: Quality 1st 面膜 · RED 预算与支出 2026-10
A2: 【填写规则】本页放置「本月已付款」的支出。若实际投放在次月及以后，请在 B列★投放月 填写实际投放的月份。
A3: 一、预算总览（自动汇总）
A4: 费用类别 | D4: 预算（元） | F4: 实际支出（元） | H4: 差额 | I4: 执行率 | J4: 预实对比表科目
A5: 筆記+直播 | F5: =SUMIF($C$18:$C$77,$A5,$G$18:$G$77) -> 0 | H5: =IF(N(D5)=0,"",D5-F5) | I5: =IF(N(D5)=0,"",F5/D5) | J5: 站外种草(Red)
A6: 直播坑位费 | F6: =SUMIF($C$18:$C$77,$A6,$G$18:$G$77) -> 0 | H6: =IF(N(D6)=0,"",D6-F6) | I6: =IF(N(D6)=0,"",F6/D6) | J6: 站外种草(Red)
A7: KOC圖文 | F7: =SUMIF($C$18:$C$77,$A7,$G$18:$G$77) -> 0 | H7: =IF(N(D7)=0,"",D7-F7) | I7: =IF(N(D7)=0,"",F7/D7) | J7: 站外种草(Red)
A8: 視頻筆記預算 | F8: =SUMIF($C$18:$C$77,$A8,$G$18:$G$77) -> 0 | H8: =IF(N(D8)=0,"",D8-F8) | I8: =IF(N(D8)=0,"",F8/D8) | J8: 站外种草(Red)
A9: koc動画不报备 | F9: =SUMIF($C$18:$C$77,$A9,$G$18:$G$77) -> 0 | H9: =IF(N(D9)=0,"",D9-F9) | I9: =IF(N(D9)=0,"",F9/D9) | J9: 站外种草(Red)
A10: 样品费 | F10: =SUMIF($C$18:$C$77,$A10,$G$18:$G$77) -> 0 | H10: =IF(N(D10)=0,"",D10-F10) | I10: =IF(N(D10)=0,"",F10/D10) | J10: ★无预算科目
A11: 运费 | F11: =SUMIF($C$18:$C$77,$A11,$G$18:$G$77) -> 0 | H11: =IF(N(D11)=0,"",D11-F11) | I11: =IF(N(D11)=0,"",F11/D11) | J11: ★无预算科目
A12: 風險保證金 | F12: =SUMIF($C$18:$C$77,$A12,$G$18:$G$77) -> 0 | H12: =IF(N(D12)=0,"",D12-F12) | I12: =IF(N(D12)=0,"",F12/D12) | J12: ★无预算科目
A13: 小紅書專業號年審費用 | F13: =SUMIF($C$18:$C$77,$A13,$G$18:$G$77) -> 0 | H13: =IF(N(D13)=0,"",D13-F13) | I13: =IF(N(D13)=0,"",F13/D13) | J13: ★无预算科目
A14: 合计 | D14: =SUM(D5:D13) -> 0 | F14: =SUM(F5:F13) -> 0 | H14: =IF(N(D14)=0,"",D14-F14) | I14: =IF(N(D14)=0,"",F14/D14)
A16: 二、支出明细 【★付款日期 与 ★投放月 为必填项。金额＝数量×单价】
A17: ★付款日期 | B17: ★投放月 | C17: 费用类别 | D17: 博主名称 | E17: 用途·合作条件 | F17: 直播产品 | G17: 金额（税入·元） | H17: 支付方式 | I17: 付款主体 | J17: 销售额（元） | K17: 投产比 | L17: 产出·笔记链接
K18: =IF(OR(N($J18)=0,N($G18)=0),"",$J18/$G18)
K19: =IF(OR(N($J19)=0,N($G19)=0),"",$J19/$G19)
K20: =IF(OR(N($J20)=0,N($G20)=0),"",$J20/$G20)
K21: =IF(OR(N($J21)=0,N($G21)=0),"",$J21/$G21)
K22: =IF(OR(N($J22)=0,N($G22)=0),"",$J22/$G22)
K23: =IF(OR(N($J23)=0,N($G23)=0),"",$J23/$G23)
K24: =IF(OR(N($J24)=0,N($G24)=0),"",$J24/$G24)
K25: =IF(OR(N($J25)=0,N($G25)=0),"",$J25/$G25)
K26: =IF(OR(N($J26)=0,N($G26)=0),"",$J26/$G26)
K27: =IF(OR(N($J27)=0,N($G27)=0),"",$J27/$G27)
K28: =IF(OR(N($J28)=0,N($G28)=0),"",$J28/$G28)
K29: =IF(OR(N($J29)=0,N($G29)=0),"",$J29/$G29)
... K77: =IF(OR(N($J77)=0,N($G77)=0),"",$J77/$G77)
A78: 合计 | G78: =SUM(G18:G77) -> 0 | J78: =SUM(J18:J77) -> 0 | K78: =IFERROR(J78/G78,"")

Sheet 2026-11
A1: Quality 1st 面膜 · RED 预算与支出 2026-11
A2: 【填写规则】本页放置「本月已付款」的支出。若实际投放在次月及以后，请在 B列★投放月 填写实际投放的月份。
A3: 一、预算总览（自动汇总）
A4: 费用类别 | D4: 预算（元） | F4: 实际支出（元） | H4: 差额 | I4: 执行率 | J4: 预实对比表科目
A5: 筆記+直播 | F5: =SUMIF($C$18:$C$77,$A5,$G$18:$G$77) -> 0 | H5: =IF(N(D5)=0,"",D5-F5) | I5: =IF(N(D5)=0,"",F5/D5) | J5: 站外种草(Red)
A6: 直播坑位费 | F6: =SUMIF($C$18:$C$77,$A6,$G$18:$G$77) -> 0 | H6: =IF(N(D6)=0,"",D6-F6) | I6: =IF(N(D6)=0,"",F6/D6) | J6: 站外种草(Red)
A7: KOC圖文 | F7: =SUMIF($C$18:$C$77,$A7,$G$18:$G$77) -> 0 | H7: =IF(N(D7)=0,"",D7-F7) | I7: =IF(N(D7)=0,"",F7/D7) | J7: 站外种草(Red)
A8: 視頻筆記預算 | F8: =SUMIF($C$18:$C$77,$A8,$G$18:$G$77) -> 0 | H8: =IF(N(D8)=0,"",D8-F8) | I8: =IF(N(D8)=0,"",F8/D8) | J8: 站外种草(Red)
A9: koc動画不报备 | F9: =SUMIF($C$18:$C$77,$A9,$G$18:$G$77) -> 0 | H9: =IF(N(D9)=0,"",D9-F9) | I9: =IF(N(D9)=0,"",F9/D9) | J9: 站外种草(Red)
A10: 样品费 | F10: =SUMIF($C$18:$C$77,$A10,$G$18:$G$77) -> 0 | H10: =IF(N(D10)=0,"",D10-F10) | I10: =IF(N(D10)=0,"",F10/D10) | J10: ★无预算科目
A11: 运费 | F11: =SUMIF($C$18:$C$77,$A11,$G$18:$G$77) -> 0 | H11: =IF(N(D11)=0,"",D11-F11) | I11: =IF(N(D11)=0,"",F11/D11) | J11: ★无预算科目
A12: 風險保證金 | F12: =SUMIF($C$18:$C$77,$A12,$G$18:$G$77) -> 0 | H12: =IF(N(D12)=0,"",D12-F12) | I12: =IF(N(D12)=0,"",F12/D12) | J12: ★无预算科目
A13: 小紅書專業號年審費用 | F13: =SUMIF($C$18:$C$77,$A13,$G$18:$G$77) -> 0 | H13: =IF(N(D13)=0,"",D13-F13) | I13: =IF(N(D13)=0,"",F13/D13) | J13: ★无预算科目
A14: 合计 | D14: =SUM(D5:D13) -> 0 | F14: =SUM(F5:F13) -> 0 | H14: =IF(N(D14)=0,"",D14-F14) | I14: =IF(N(D14)=0,"",F14/D14)
A16: 二、支出明细 【★付款日期 与 ★投放月 为必填项。金额＝数量×单价】
A17: ★付款日期 | B17: ★投放月 | C17: 费用类别 | D17: 博主名称 | E17: 用途·合作条件 | F17: 直播产品 | G17: 金额（税入·元） | H17: 支付方式 | I17: 付款主体 | J17: 销售额（元） | K17: 投产比 | L17: 产出·笔记链接
K18: =IF(OR(N($J18)=0,N($G18)=0),"",$J18/$G18)
K19: =IF(OR(N($J19)=0,N($G19)=0),"",$J19/$G19)
K20: =IF(OR(N($J20)=0,N($G20)=0),"",$J20/$G20)
K21: =IF(OR(N($J21)=0,N($G21)=0),"",$J21/$G21)
K22: =IF(OR(N($J22)=0,N($G22)=0),"",$J22/$G22)
K23: =IF(OR(N($J23)=0,N($G23)=0),"",$J23/$G23)
K24: =IF(OR(N($J24)=0,N($G24)=0),"",$J24/$G24)
K25: =IF(OR(N($J25)=0,N($G25)=0),"",$J25/$G25)
K26: =IF(OR(N($J26)=0,N($G26)=0),"",$J26/$G26)
K27: =IF(OR(N($J27)=0,N($G27)=0),"",$J27/$G27)
K28: =IF(OR(N($J28)=0,N($G28)=0),"",$J28/$G28)
K29: =IF(OR(N($J29)=0,N($G29)=0),"",$J29/$G29)
... K77: =IF(OR(N($J77)=0,N($G77)=0),"",$J77/$G77)
A78: 合计 | G78: =SUM(G18:G77) -> 0 | J78: =SUM(J18:J77) -> 0 | K78: =IFERROR(J78/G78,"")

Sheet 2026-12
A1: Quality 1st 面膜 · RED 预算与支出 2026-12
A2: 【填写规则】本页放置「本月已付款」的支出。若实际投放在次月及以后，请在 B列★投放月 填写实际投放的月份。
A3: 一、预算总览（自动汇总）
A4: 费用类别 | D4: 预算（元） | F4: 实际支出（元） | H4: 差额 | I4: 执行率 | J4: 预实对比表科目
A5: 筆記+直播 | F5: =SUMIF($C$18:$C$77,$A5,$G$18:$G$77) -> 0 | H5: =IF(N(D5)=0,"",D5-F5) | I5: =IF(N(D5)=0,"",F5/D5) | J5: 站外种草(Red)
A6: 直播坑位费 | F6: =SUMIF($C$18:$C$77,$A6,$G$18:$G$77) -> 0 | H6: =IF(N(D6)=0,"",D6-F6) | I6: =IF(N(D6)=0,"",F6/D6) | J6: 站外种草(Red)
A7: KOC圖文 | F7: =SUMIF($C$18:$C$77,$A7,$G$18:$G$77) -> 0 | H7: =IF(N(D7)=0,"",D7-F7) | I7: =IF(N(D7)=0,"",F7/D7) | J7: 站外种草(Red)
A8: 視頻筆記預算 | F8: =SUMIF($C$18:$C$77,$A8,$G$18:$G$77) -> 0 | H8: =IF(N(D8)=0,"",D8-F8) | I8: =IF(N(D8)=0,"",F8/D8) | J8: 站外种草(Red)
A9: koc動画不报备 | F9: =SUMIF($C$18:$C$77,$A9,$G$18:$G$77) -> 0 | H9: =IF(N(D9)=0,"",D9-F9) | I9: =IF(N(D9)=0,"",F9/D9) | J9: 站外种草(Red)
A10: 样品费 | F10: =SUMIF($C$18:$C$77,$A10,$G$18:$G$77) -> 0 | H10: =IF(N(D10)=0,"",D10-F10) | I10: =IF(N(D10)=0,"",F10/D10) | J10: ★无预算科目
A11: 运费 | F11: =SUMIF($C$18:$C$77,$A11,$G$18:$G$77) -> 0 | H11: =IF(N(D11)=0,"",D11-F11) | I11: =IF(N(D11)=0,"",F11/D11) | J11: ★无预算科目
A12: 風險保證金 | F12: =SUMIF($C$18:$C$77,$A12,$G$18:$G$77) -> 0 | H12: =IF(N(D12)=0,"",D12-F12) | I12: =IF(N(D12)=0,"",F12/D12) | J12: ★无预算科目
A13: 小紅書專業號年審費用 | F13: =SUMIF($C$18:$C$77,$A13,$G$18:$G$77) -> 0 | H13: =IF(N(D13)=0,"",D13-F13) | I13: =IF(N(D13)=0,"",F13/D13) | J13: ★无预算科目
A14: 合计 | D14: =SUM(D5:D13) -> 0 | F14: =SUM(F5:F13) -> 0 | H14: =IF(N(D14)=0,"",D14-F14) | I14: =IF(N(D14)=0,"",F14/D14)
A16: 二、支出明细 【★付款日期 与 ★投放月 为必填项。金额＝数量×单价】
A17: ★付款日期 | B17: ★投放月 | C17: 费用类别 | D17: 博主名称 | E17: 用途·合作条件 | F17: 直播产品 | G17: 金额（税入·元） | H17: 支付方式 | I17: 付款主体 | J17: 销售额（元） | K17: 投产比 | L17: 产出·笔记链接
K18: =IF(OR(N($J18)=0,N($G18)=0),"",$J18/$G18)
K19: =IF(OR(N($J19)=0,N($G19)=0),"",$J19/$G19)
K20: =IF(OR(N($J20)=0,N($G20)=0),"",$J20/$G20)
K21: =IF(OR(N($J21)=0,N($G21)=0),"",$J21/$G21)
K22: =IF(OR(N($J22)=0,N($G22)=0),"",$J22/$G22)
K23: =IF(OR(N($J23)=0,N($G23)=0),"",$J23/$G23)
K24: =IF(OR(N($J24)=0,N($G24)=0),"",$J24/$G24)
K25: =IF(OR(N($J25)=0,N($G25)=0),"",$J25/$G25)
K26: =IF(OR(N($J26)=0,N($G26)=0),"",$J26/$G26)
K27: =IF(OR(N($J27)=0,N($G27)=0),"",$J27/$G27)
K28: =IF(OR(N($J28)=0,N($G28)=0),"",$J28/$G28)
K29: =IF(OR(N($J29)=0,N($G29)=0),"",$J29/$G29)
... K77: =IF(OR(N($J77)=0,N($G77)=0),"",$J77/$G77)
A78: 合计 | G78: =SUM(G18:G77) -> 0 | J78: =SUM(J18:J77) -> 0 | K78: =IFERROR(J78/G78,"")
